Workbook

Sheet Leia primeiro
A1: Classificação fiscal para emissão de NFC-e — VL GASTRONOMIA LTDA (El Patrón)
A2: CNPJ 58.193.623/0001-08 · Pontal do Paraná/PR · CNAE 56.11-2-01 Restaurantes e similares · IE 9111014830
A4: O que é esta planilha
A5: O sistema de vendas (ERPOS) vai emitir uma NFC-e (modelo 65) automaticamente a cada venda paga. Para a nota sair correta, cada produto precisa dos códigos fiscais abaixo. Esta planilha lista todos os produtos do cardápio para você preencher/validar.
A7: Como preencher
A8: 1. Aba EMPRESA: confirme o regime tributário e os padrões da loja (vale para todo produto que não tiver código próprio).
A9: 2. Aba CATEGORIAS: preencha os códigos por categoria. A maioria dos produtos herda daqui — é o jeito rápido.
A10: 3. Aba PRODUTOS: só precisa preencher onde o produto for exceção à categoria (ex.: água dentro de Bebidas, soda sem álcool dentro de Drinks). Deixe em branco para herdar.
A11: 4. Células AMARELAS são para você preencher. Células VERDES são sugestões do sistema — pode manter ou corrigir.
A12: 5. As colunas CFOP, CSOSN e Origem têm lista suspensa. NCM: 8 dígitos sem ponto (ex.: 21069090). CEST: 7 dígitos, só quando houver substituição tributária.
A14: Regra de herança usada pelo sistema
A15: Produto → Categoria → Padrão da loja (aba EMPRESA). O primeiro nível preenchido vence.
... A26: Dúvidas: Natalino — natalinojr.engel@gmail.com · (41) 93844-1497

Sheet Empresa
A1: Item | B1: Valor (preencher/confirmar) | C1: Observação
A2: Razão social | B2: VL GASTRONOMIA LTDA | C2: Como está no cadastro do Brasil NFe
A3: CNPJ | B3: 58.193.623/0001-08
A4: Inscrição estadual | B4: 9111014830 | C4: Confirmar
A5: CNAE principal | B5: 56.11-2-01 Restaurantes e similares
A6: Endereço | B6: Rua Lauro Teixeira Neto, 243 - Praia de Leste - Pontal do Paraná/PR - CEP 83255-010 | C6: Confirmar
A7: Regime tributário (CRT) | B7: 1 - Simples Nacional | C7: 1 Simples · 2 Simples excesso sublimite · 3 Regime Normal · 4 MEI
A8: Natureza da operação | B8: VENDA DE MERCADORIA
A9: CFOP padrão (venda dentro do estado) | B9: 5102 | C9: 5102 revenda / 5101 produção própria / 5405 ST. Ver aba Legenda
A10: CSOSN padrão (Simples) | B10: 102 | C10: 102 sem crédito · 500 ICMS cobrado por ST · ver Legenda
A11: NCM padrão (comida preparada) | B11: 21069090 | C11: Usado em todo item sem NCM próprio
A12: Origem padrão da mercadoria | B12: 0 - Nacional
A13: CST PIS padrão | B13: 49 | C13: Simples Nacional: 49 outras operações de saída
A14: CST COFINS padrão | B14: 49
A15: Alíquota aprox. de tributos (Lei 12.741) — comida | C15: Percentual para o campo 'tributos aproximados' do cupom, se quiser informar
A16: Alíquota aprox. de tributos (Lei 12.741) — bebidas
A17: Certificado A1 | B17: Já cadastrado no provedor (vence 03/12/2026) | C17: Lembrete de renovação
A18: CSC NFC-e produção / homologação | B18: Já cadastrados (Id 000002 / 000001)
A19: Credenciamento NFC-e na Receita/PR | C19: Confirmar que a empresa está credenciada a emitir NFC-e (mod. 65)
A20: Série da NFC-e | B20: 1 (automática) | C20: Informar se precisar de outra série
A21: Observações da contadora

Sheet Categorias
A1: Categoria | B1: O que é | C1: Qtd. produtos | D1: NCM sugerido | E1: NCM (contadora) | F1: CEST | G1: CFOP | H1: CSOSN | I1: Tem ICMS-ST? (S/N) | J1: Observação da contadora
A2: Hamburguer | B2: Comida preparada na casa | C2: =COUNTIF(Produtos!$A:$A,A2) | D2: 21069090
A3: Burrito | B3: Comida preparada na casa | C3: =COUNTIF(Produtos!$A:$A,A3) | D3: 21069090
A4: Quesadillas | B4: Comida preparada na casa | C4: =COUNTIF(Produtos!$A:$A,A4) | D4: 21069090
A5: Tacos | B5: Comida preparada na casa | C5: =COUNTIF(Produtos!$A:$A,A5) | D5: 21069090
A6: Nachos | B6: Comida preparada na casa | C6: =COUNTIF(Produtos!$A:$A,A6) | D6: 21069090
A7: Pasteis | B7: Pastéis fritos na casa (salgados e doces) | C7: =COUNTIF(Produtos!$A:$A,A7) | D7: 21069090
A8: Porções | B8: Porções fritas preparadas na casa | C8: =COUNTIF(Produtos!$A:$A,A8) | D8: 21069090
A9: Espetinhos | B9: Espetinhos grelhados na casa | C9: =COUNTIF(Produtos!$A:$A,A9) | D9: 21069090
A10: Churros | B10: Doce preparado na casa | C10: =COUNTIF(Produtos!$A:$A,A10) | D10: 21069090
A11: Extras | B11: Molhos e acompanhamentos preparados na casa | C11: =COUNTIF(Produtos!$A:$A,A11) | D11: 21069090
A12: Bebidas | B12: Refrigerantes, néctares e água (revenda de industrializados) | C12: =COUNTIF(Produtos!$A:$A,A12) | D12: 22021000
A13: Sucos | B13: Sucos naturais feitos na hora | C13: =COUNTIF(Produtos!$A:$A,A13) | D13: 22029900
... A16: Chopes | B16: Chope de barril servido no copo | C16: =COUNTIF(Produtos!$A:$A,A16) | D16: 22030000
A18: Preencha o NCM na coluna E só se for diferente do sugerido (D). Em branco = o sistema usa o sugerido. CEST só quando 'Tem ICMS-ST' = S.

Sheet Produtos
A1: Categoria | B1: Produto | C1: Descrição / composição | D1: Preço (R$) | E1: Ativo | F1: NCM herdado | G1: NCM (só se for exceção) | H1: CEST | I1: CFOP | J1: CSOSN | K1: Origem | L1: Código de barras (GTIN) | M1: Observação da contadora
A2: Hamburguer | B2: Hamburguer de Bacon | C2: Carne bovina 100g, pão, cheddar, cebola caramelizada, bacon, molho | D2: 25.9 | E2: Sim | F2: =IF(INDEX(Categorias!$E:$E,MATCH(A2,Categorias!$A:$A,0))<>"",INDEX(Categorias!$E:$E,MATCH(A2,Categorias!$A:$A,0)),IF(INDEX(Categorias!$D:$D,MATCH(A2,Categorias!$A:$A,0))<>"",INDEX(Categorias!$D:$D,MATCH(A2,Categorias!$A:$A,0)),Empresa!$B$11))
A3: Hamburguer | B3: Hamburguer de Frango | C3: Hambúrguer de frango 100g, pão, provolone, alface, tomate, molho | D3: 25.9 | E3: Sim | F3: =IF(INDEX(Categorias!$E:$E,MATCH(A3,Categorias!$A:$A,0))<>"",INDEX(Categorias!$E:$E,MATCH(A3,Categorias!$A:$A,0)),IF(INDEX(Categorias!$D:$D,MATCH(A3,Categorias!$A:$A,0))<>"",INDEX(Categorias!$D:$D,MATCH(A3,Categorias!$A:$A,0)),Empresa!$B$11))
A4: Hamburguer | B4: Hamburguer de Frango + Batata frita | C4: Hambúrguer de frango 180g, pão brioche, provolone, salada + batata | D4: 40 | E4: Sim | F4: =IF(INDEX(Categorias!$E:$E,MATCH(A4,Categorias!$A:$A,0))<>"",INDEX(Categorias!$E:$E,MATCH(A4,Categorias!$A:$A,0)),IF(INDEX(Categorias!$D:$D,MATCH(A4,Categorias!$A:$A,0))<>"",INDEX(Categorias!$D:$D,MATCH(A4,Categorias!$A:$A,0)),Empresa!$B$11))
A5: Hamburguer | B5: Hamburguer Salada | C5: Carne bovina 100g, pão, alface, tomate, molho verde | D5: 25.9 | E5: Sim | F5: =IF(INDEX(Categorias!$E:$E,MATCH(A5,Categorias!$A:$A,0))<>"",INDEX(Categorias!$E:$E,MATCH(A5,Categorias!$A:$A,0)),IF(INDEX(Categorias!$D:$D,MATCH(A5,Categorias!$A:$A,0))<>"",INDEX(Categorias!$D:$D,MATCH(A5,Categorias!$A:$A,0)),Empresa!$B$11))
A6: Hamburguer | B6: Hamburguer Sour Salad + Batata frita | C6: Carne bovina 180g na brasa, brioche, salada, sour cream + batata | D6: 40 | E6: Sim | F6: =IF(INDEX(Categorias!$E:$E,MATCH(A6,Categorias!$A:$A,0))<>"",INDEX(Categorias!$E:$E,MATCH(A6,Categorias!$A:$A,0)),IF(INDEX(Categorias!$D:$D,MATCH(A6,Categorias!$A:$A,0))<>"",INDEX(Categorias!$D:$D,MATCH(A6,Categorias!$A:$A,0)),Empresa!$B$11))
A7: Hamburguer | B7: Hamburguer de Bacon + Batata frita | C7: Carne bovina 180g, brioche, cheddar, cebola caramelizada, bacon + batata | D7: 40 | E7: Sim | F7: =IF(INDEX(Categorias!$E:$E,MATCH(A7,Categorias!$A:$A,0))<>"",INDEX(Categorias!$E:$E,MATCH(A7,Categorias!$A:$A,0)),IF(INDEX(Categorias!$D:$D,MATCH(A7,Categorias!$A:$A,0))<>"",INDEX(Categorias!$D:$D,MATCH(A7,Categorias!$A:$A,0)),Empresa!$B$11))
A8: Hamburguer | B8: Tortilha burguer + batata frita | C8: Tortilha de trigo, carne 180g, cebola, bacon, cheddar, salada, barbecue + batata | D8: 40 | E8: Sim | F8: =IF(INDEX(Categorias!$E:$E,MATCH(A8,Categorias!$A:$A,0))<>"",INDEX(Categorias!$E:$E,MATCH(A8,Categorias!$A:$A,0)),IF(INDEX(Categorias!$D:$D,MATCH(A8,Categorias!$A:$A,0))<>"",INDEX(Categorias!$D:$D,MATCH(A8,Categorias!$A:$A,0)),Empresa!$B$11))
A9: Burrito | B9: Burritos Duo Mex | C9: Promoção: 2ª unidade com 50% de desconto | D9: 0 | E9: Não | F9: =IF(INDEX(Categorias!$E:$E,MATCH(A9,Categorias!$A:$A,0))<>"",INDEX(Categorias!$E:$E,MATCH(A9,Categorias!$A:$A,0)),IF(INDEX(Categorias!$D:$D,MATCH(A9,Categorias!$A:$A,0))<>"",INDEX(Categorias!$D:$D,MATCH(A9,Categorias!$A:$A,0)),Empresa!$B$11))
A10: Burrito | B10: Burrito Classic Veggie | C10: Tortilla, chilli de soja, cheddar, alface, tomate, milho, jalapeño | D10: 38 | E10: Sim | F10: =IF(INDEX(Categorias!$E:$E,MATCH(A10,Categorias!$A:$A,0))<>"",INDEX(Categorias!$E:$E,MATCH(A10,Categorias!$A:$A,0)),IF(INDEX(Categorias!$D:$D,MATCH(A10,Categorias!$A:$A,0))<>"",INDEX(Categorias!$D:$D,MATCH(A10,Categorias!$A:$A,0)),Empresa!$B$11))
A11: Burrito | B11: Burrito California | C11: Tortilla, barbacoa, batata frita, pico de galo, guacamole, sour cream | D11: 45 | E11: Sim | F11: =IF(INDEX(Categorias!$E:$E,MATCH(A11,Categorias!$A:$A,0))<>"",INDEX(Categorias!$E:$E,MATCH(A11,Categorias!$A:$A,0)),IF(INDEX(Categorias!$D:$D,MATCH(A11,Categorias!$A:$A,0))<>"",INDEX(Categorias!$D:$D,MATCH(A11,Categorias!$A:$A,0)),Empresa!$B$11))
A12: Burrito | B12: Burrito Barbacoa | C12: Tortilla, barbacoa, mussarela, jalapeño, pico de galo, alface, rúcula | D12: 41 | E12: Sim | F12: =IF(INDEX(Categorias!$E:$E,MATCH(A12,Categorias!$A:$A,0))<>"",INDEX(Categorias!$E:$E,MATCH(A12,Categorias!$A:$A,0)),IF(INDEX(Categorias!$D:$D,MATCH(A12,Categorias!$A:$A,0))<>"",INDEX(Categorias!$D:$D,MATCH(A12,Categorias!$A:$A,0)),Empresa!$B$11))
A13: Burrito | B13: Burrito Al Pastor | C13: Tortilla, pernil, bacon, pasta de feijão, abacaxi, cheddar, barbecue | D13: 38 | E13: Sim | F13: =IF(INDEX(Categorias!$E:$E,MATCH(A13,Categorias!$A:$A,0))<>"",INDEX(Categorias!$E:$E,MATCH(A13,Categorias!$A:$A,0)),IF(INDEX(Categorias!$D:$D,MATCH(A13,Categorias!$A:$A,0))<>"",INDEX(Categorias!$D:$D,MATCH(A13,Categorias!$A:$A,0)),Empresa!$B$11))
... A19: Quesadillas | B19: Quesadilla Chilli con Carne | C19: Tortilla, chilli con carne, mussarela, cheddar | D19: 21 | E19: Sim | F19: =IF(INDEX(Categorias!$E:$E,MATCH(A19,Categorias!$A:$A,0))<>"",INDEX(Categorias!$E:$E,MATCH(A19,Categorias!$A:$A,0)),IF(INDEX(Categorias!$D:$D,MATCH(A19,Categorias!$A:$A,0))<>"",INDEX(Categorias!$D:$D,MATCH(A19,Categorias!$A:$A,0)),Empresa!$B$11))
A20: Quesadillas | B20: Quesadilla ovomaltine | C20: Tortilla, chocolate branco Ovomaltine, mussarela (doce) | D20: 18 | E20: Sim | F20: =IF(INDEX(Categorias!$E:$E,MATCH(A20,Categorias!$A:$A,0))<>"",INDEX(Categorias!$E:$E,MATCH(A20,Categorias!$A:$A,0)),IF(INDEX(Categorias!$D:$D,MATCH(A20,Categorias!$A:$A,0))<>"",INDEX(Categorias!$D:$D,MATCH(A20,Categorias!$A:$A,0)),Empresa!$B$11)) | M20: ⚠ Doce: mantém 21069090?
A21: Tacos | B21: Trio de tacos | C21: 3 tacos: classic, caliente e al pastor | D21: 44 | E21: Sim | F21: =IF(INDEX(Categorias!$E:$E,MATCH(A21,Categorias!$A:$A,0))<>"",INDEX(Categorias!$E:$E,MATCH(A21,Categorias!$A:$A,0)),IF(INDEX(Categorias!$D:$D,MATCH(A21,Categorias!$A:$A,0))<>"",INDEX(Categorias!$D:$D,MATCH(A21,Categorias!$A:$A,0)),Empresa!$B$11))
A22: Nachos | B22: Nachos Chilli con Carne | C22: Tortilla chips, chilli con carne, cheddar, mussarela, guacamole, sour cream | D22: 38 | E22: Sim | F22: =IF(INDEX(Categorias!$E:$E,MATCH(A22,Categorias!$A:$A,0))<>"",INDEX(Categorias!$E:$E,MATCH(A22,Categorias!$A:$A,0)),IF(INDEX(Categorias!$D:$D,MATCH(A22,Categorias!$A:$A,0))<>"",INDEX(Categorias!$D:$D,MATCH(A22,Categorias!$A:$A,0)),Empresa!$B$11))
A23: Pasteis | B23: Pastel abacaxi gelado | C23: Pastel doce: chocolate branco, abacaxi e coco | D23: 18 | E23: Sim | F23: =IF(INDEX(Categorias!$E:$E,MATCH(A23,Categorias!$A:$A,0))<>"",INDEX(Categorias!$E:$E,MATCH(A23,Categorias!$A:$A,0)),IF(INDEX(Categorias!$D:$D,MATCH(A23,Categorias!$A:$A,0))<>"",INDEX(Categorias!$D:$D,MATCH(A23,Categorias!$A:$A,0)),Empresa!$B$11)) | M23: ⚠ Doce: mantém NCM da categoria?
A24: Pasteis | B24: Pastel de carne | C24: Carne, mussarela e ovo | D24: 18 | E24: Sim | F24: =IF(INDEX(Categorias!$E:$E,MATCH(A24,Categorias!$A:$A,0))<>"",INDEX(Categorias!$E:$E,MATCH(A24,Categorias!$A:$A,0)),IF(INDEX(Categorias!$D:$D,MATCH(A24,Categorias!$A:$A,0))<>"",INDEX(Categorias!$D:$D,MATCH(A24,Categorias!$A:$A,0)),Empresa!$B$11))
A25: Pasteis | B25: Pastel sensação caribe | C25: Pastel doce: chocolate branco, morango e coco | D25: 18 | E25: Sim | F25: =IF(INDEX(Categorias!$E:$E,MATCH(A25,Categorias!$A:$A,0))<>"",INDEX(Categorias!$E:$E,MATCH(A25,Categorias!$A:$A,0)),IF(INDEX(Categorias!$D:$D,MATCH(A25,Categorias!$A:$A,0))<>"",INDEX(Categorias!$D:$D,MATCH(A25,Categorias!$A:$A,0)),Empresa!$B$11)) | M25: ⚠ Doce: mantém NCM da categoria?
A26: Pasteis | B26: Pastel de queijo | C26: Queijo mussarela | D26: 18 | E26: Sim | F26: =IF(INDEX(Categorias!$E:$E,MATCH(A26,Categorias!$A:$A,0))<>"",INDEX(Categorias!$E:$E,MATCH(A26,Categorias!$A:$A,0)),IF(INDEX(Categorias!$D:$D,MATCH(A26,Categorias!$A:$A,0))<>"",INDEX(Categorias!$D:$D,MATCH(A26,Categorias!$A:$A,0)),Empresa!$B$11))
A27: Pasteis | B27: Pastel calabresa | C27: Calabresa e mussarela | D27: 18 | E27: Sim | F27: =IF(INDEX(Categorias!$E:$E,MATCH(A27,Categorias!$A:$A,0))<>"",INDEX(Categorias!$E:$E,MATCH(A27,Categorias!$A:$A,0)),IF(INDEX(Categorias!$D:$D,MATCH(A27,Categorias!$A:$A,0))<>"",INDEX(Categorias!$D:$D,MATCH(A27,Categorias!$A:$A,0)),Empresa!$B$11))
A28: Pasteis | B28: Pastel palmito | C28: Palmito e mussarela | D28: 18 | E28: Não | F28: =IF(INDEX(Categorias!$E:$E,MATCH(A28,Categorias!$A:$A,0))<>"",INDEX(Categorias!$E:$E,MATCH(A28,Categorias!$A:$A,0)),IF(INDEX(Categorias!$D:$D,MATCH(A28,Categorias!$A:$A,0))<>"",INDEX(Categorias!$D:$D,MATCH(A28,Categorias!$A:$A,0)),Empresa!$B$11))
A29: Pasteis | B29: Pastel de frango | C29: Frango, mussarela, catupiry | D29: 18 | E29: Sim | F29: =IF(INDEX(Categorias!$E:$E,MATCH(A29,Categorias!$A:$A,0))<>"",INDEX(Categorias!$E:$E,MATCH(A29,Categorias!$A:$A,0)),IF(INDEX(Categorias!$D:$D,MATCH(A29,Categorias!$A:$A,0))<>"",INDEX(Categorias!$D:$D,MATCH(A29,Categorias!$A:$A,0)),Empresa!$B$11))
A30: Pasteis | B30: Frango caipira | C30: Pastel: frango, mussarela, ovo, bacon, milho | D30: 25 | E30: Sim | F30: =IF(INDEX(Categorias!$E:$E,MATCH(A30,Categorias!$A:$A,0))<>"",INDEX(Categorias!$E:$E,MATCH(A30,Categorias!$A:$A,0)),IF(INDEX(Categorias!$D:$D,MATCH(A30,Categorias!$A:$A,0))<>"",INDEX(Categorias!$D:$D,MATCH(A30,Categorias!$A:$A,0)),Empresa!$B$11))
A31: Pasteis | B31: Pastel crocante | C31: Frango, mussarela, catupiry, bacon, batata palha | D31: 25 | E31: Sim | F31: =IF(INDEX(Categorias!$E:$E,MATCH(A31,Categorias!$A:$A,0))<>"",INDEX(Categorias!$E:$E,MATCH(A31,Categorias!$A:$A,0)),IF(INDEX(Categorias!$D:$D,MATCH(A31,Categorias!$A:$A,0))<>"",INDEX(Categorias!$D:$D,MATCH(A31,Categorias!$A:$A,0)),Empresa!$B$11))
A32: Pasteis | B32: Pastel mexicano | C32: Chilli con carne, mussarela, calabresa, cheddar, doritos | D32: 25 | E32: Sim | F32: =IF(INDEX(Categorias!$E:$E,MATCH(A32,Categorias!$A:$A,0))<>"",INDEX(Categorias!$E:$E,MATCH(A32,Categorias!$A:$A,0)),IF(INDEX(Categorias!$D:$D,MATCH(A32,Categorias!$A:$A,0))<>"",INDEX(Categorias!$D:$D,MATCH(A32,Categorias!$A:$A,0)),Empresa!$B$11))
A33: Pasteis | B33: Pastel a portuguesa | C33: Mussarela, presunto, ovo, cebola crispy | D33: 25 | E33: Sim | F33: =IF(INDEX(Categorias!$E:$E,MATCH(A33,Categorias!$A:$A,0))<>"",INDEX(Categorias!$E:$E,MATCH(A33,Categorias!$A:$A,0)),IF(INDEX(Categorias!$D:$D,MATCH(A33,Categorias!$A:$A,0))<>"",INDEX(Categorias!$D:$D,MATCH(A33,Categorias!$A:$A,0)),Empresa!$B$11))
A34: Pasteis | B34: Pastel tudo | C34: Carne, mussarela, calabresa, palmito, frango, presunto | D34: 25 | E34: Sim | F34: =IF(INDEX(Categorias!$E:$E,MATCH(A34,Categorias!$A:$A,0))<>"",INDEX(Categorias!$E:$E,MATCH(A34,Categorias!$A:$A,0)),IF(INDEX(Categorias!$D:$D,MATCH(A34,Categorias!$A:$A,0))<>"",INDEX(Categorias!$D:$D,MATCH(A34,Categorias!$A:$A,0)),Empresa!$B$11))
A35: Porções | B35: Batata frita | C35: 400 g de batata frita com molho | D35: 35 | E35: Sim | F35: =IF(INDEX(Categorias!$E:$E,MATCH(A35,Categorias!$A:$A,0))<>"",INDEX(Categorias!$E:$E,MATCH(A35,Categorias!$A:$A,0)),IF(INDEX(Categorias!$D:$D,MATCH(A35,Categorias!$A:$A,0))<>"",INDEX(Categorias!$D:$D,MATCH(A35,Categorias!$A:$A,0)),Empresa!$B$11))
A36: Porções | B36: Batata frita com chedder e bacon | C36: 400 g de batata frita | D36: 40 | E36: Sim | F36: =IF(INDEX(Categorias!$E:$E,MATCH(A36,Categorias!$A:$A,0))<>"",INDEX(Categorias!$E:$E,MATCH(A36,Categorias!$A:$A,0)),IF(INDEX(Categorias!$D:$D,MATCH(A36,Categorias!$A:$A,0))<>"",INDEX(Categorias!$D:$D,MATCH(A36,Categorias!$A:$A,0)),Empresa!$B$11))
A37: Porções | B37: Batata frita com 4 queijos e bacon | C37: 400 g de batata frita | D37: 45 | E37: Sim | F37: =IF(INDEX(Categorias!$E:$E,MATCH(A37,Categorias!$A:$A,0))<>"",INDEX(Categorias!$E:$E,MATCH(A37,Categorias!$A:$A,0)),IF(INDEX(Categorias!$D:$D,MATCH(A37,Categorias!$A:$A,0))<>"",INDEX(Categorias!$D:$D,MATCH(A37,Categorias!$A:$A,0)),Empresa!$B$11))
... A41: Porções | B41: Camarão empanado | C41: 400 g de camarão empanado | D41: 70 | E41: Não | F41: =IF(INDEX(Categorias!$E:$E,MATCH(A41,Categorias!$A:$A,0))<>"",INDEX(Categorias!$E:$E,MATCH(A41,Categorias!$A:$A,0)),IF(INDEX(Categorias!$D:$D,MATCH(A41,Categorias!$A:$A,0))<>"",INDEX(Categorias!$D:$D,MATCH(A41,Categorias!$A:$A,0)),Empresa!$B$11))
A42: Espetinhos | B42: Espetinho de Carne com bacon | D42: 15 | E42: Não | F42: =IF(INDEX(Categorias!$E:$E,MATCH(A42,Categorias!$A:$A,0))<>"",INDEX(Categorias!$E:$E,MATCH(A42,Categorias!$A:$A,0)),IF(INDEX(Categorias!$D:$D,MATCH(A42,Categorias!$A:$A,0))<>"",INDEX(Categorias!$D:$D,MATCH(A42,Categorias!$A:$A,0)),Empresa!$B$11))
A43: Espetinhos | B43: Espetinho de coração | D43: 12 | E43: Não | F43: =IF(INDEX(Categorias!$E:$E,MATCH(A43,Categorias!$A:$A,0))<>"",INDEX(Categorias!$E:$E,MATCH(A43,Categorias!$A:$A,0)),IF(INDEX(Categorias!$D:$D,MATCH(A43,Categorias!$A:$A,0))<>"",INDEX(Categorias!$D:$D,MATCH(A43,Categorias!$A:$A,0)),Empresa!$B$11))
A44: Espetinhos | B44: Espetinho de queijo coalho | D44: 12 | E44: Sim | F44: =IF(INDEX(Categorias!$E:$E,MATCH(A44,Categorias!$A:$A,0))<>"",INDEX(Categorias!$E:$E,MATCH(A44,Categorias!$A:$A,0)),IF(INDEX(Categorias!$D:$D,MATCH(A44,Categorias!$A:$A,0))<>"",INDEX(Categorias!$D:$D,MATCH(A44,Categorias!$A:$A,0)),Empresa!$B$11))
A45: Espetinhos | B45: Pão de alho | D45: 12 | E45: Sim | F45: =IF(INDEX(Categorias!$E:$E,MATCH(A45,Categorias!$A:$A,0))<>"",INDEX(Categorias!$E:$E,MATCH(A45,Categorias!$A:$A,0)),IF(INDEX(Categorias!$D:$D,MATCH(A45,Categorias!$A:$A,0))<>"",INDEX(Categorias!$D:$D,MATCH(A45,Categorias!$A:$A,0)),Empresa!$B$11))
A46: Espetinhos | B46: Espetinho de kafta | D46: 15 | E46: Não | F46: =IF(INDEX(Categorias!$E:$E,MATCH(A46,Categorias!$A:$A,0))<>"",INDEX(Categorias!$E:$E,MATCH(A46,Categorias!$A:$A,0)),IF(INDEX(Categorias!$D:$D,MATCH(A46,Categorias!$A:$A,0))<>"",INDEX(Categorias!$D:$D,MATCH(A46,Categorias!$A:$A,0)),Empresa!$B$11))
A47: Espetinhos | B47: Espetinho asinha de frango | D47: 12 | E47: Não | F47: =IF(INDEX(Categorias!$E:$E,MATCH(A47,Categorias!$A:$A,0))<>"",INDEX(Categorias!$E:$E,MATCH(A47,Categorias!$A:$A,0)),IF(INDEX(Categorias!$D:$D,MATCH(A47,Categorias!$A:$A,0))<>"",INDEX(Categorias!$D:$D,MATCH(A47,Categorias!$A:$A,0)),Empresa!$B$11))
A48: Churros | B48: Churros | C48: 8 unidades de churros | D48: 25 | E48: Sim | F48: =IF(INDEX(Categorias!$E:$E,MATCH(A48,Categorias!$A:$A,0))<>"",INDEX(Categorias!$E:$E,MATCH(A48,Categorias!$A:$A,0)),IF(INDEX(Categorias!$D:$D,MATCH(A48,Categorias!$A:$A,0))<>"",INDEX(Categorias!$D:$D,MATCH(A48,Categorias!$A:$A,0)),Empresa!$B$11))
...

Sheet Legenda
A1: CSOSN | H1: 102 | I1: 5102 | J1: 0
A2: 102 | B2: Tributada pelo Simples sem permissão de crédito (padrão) | H2: 101 | I2: 5101 | J2: 1
A3: 101 | B3: Tributada pelo Simples com permissão de crédito | H3: 103 | I3: 5405 | J3: 2
A4: 103 | B4: Isenção do ICMS no Simples (faixa de receita) | H4: 300 | I4: 5403
A5: 300 | B5: Imune | H5: 400
A6: 400 | B6: Não tributada pelo Simples | H6: 500
A7: 500 | B7: ICMS cobrado anteriormente por substituição tributária (bebidas, cigarros) | H7: 900
A8: 900 | B8: Outros
A10: CFOP
A11: 5102 | B11: Venda de mercadoria adquirida de terceiros (revenda)
A12: 5101 | B12: Venda de produção do estabelecimento
A13: 5405 | B13: Venda de mercadoria sujeita a ST, na condição de substituído
A14: 5403 | B14: Venda de mercadoria sujeita a ST, na condição de substituto
A16: ORIGEM
A17: 0 | B17: Nacional
A18: 1 | B18: Estrangeira - importação direta
A19: 2 | B19: Estrangeira - adquirida no mercado interno
A21: NCM sugeridos
A22: 21069090 | B22: Preparações alimentícias não especificadas (pratos, lanches, porções)
A23: 19059090 | B23: Produtos de padaria/pastelaria (pães, pastéis, tortas)
A24: 22021000 | B24: Refrigerantes e águas com açúcar/aromatizadas
A25: 22019000 | B25: Água mineral sem gás
A26: 22011000 | B26: Água mineral com gás
A27: 22030000 | B27: Cerveja e chope
A28: 22089000 | B28: Bebidas destiladas e drinks alcoólicos
A29: 22042100 | B29: Vinho
A30: 22029900 | B30: Sucos e bebidas não alcoólicas (outras)
A31: 20099000 | B31: Sucos de frutas (misturas)
A32: 21050010 | B32: Sorvete
A33: 18063100 | B33: Chocolates e sobremesas de chocolate
